Workbook

Sheet Legenda e metodo
A1: Stato dell’arte su FPGA — SHA3-256 / SHA3-512 / Ascon-Hash: punti del fronte di Pareto
A2: Metodologia: docs/reports/posizionamento_sota.md (repo ascon-sha3-hybrid-hls), estesa ai vendor non AMD e ai lavori in slice. Generato il 30/10/2026.
A4: Come leggere i fogli
A5: • Ogni foglio raccoglie i lavori per vendor e unità d’area dichiarata: AMD – LUT, AMD – slice, Intel (ALM, ALUT, LE, "slice" non definita), HLS.
A6: • Altre architetture: vendor diversi da AMD e Intel (Lattice, Microchip). LUT a 4 ingressi, non confrontabili direttamente con i LUT6 AMD né con gli ALM/LE Intel: dati di contesto, con il confronto dello stesso RTL su tre famiglie (GMU Round 2).
A7: • Nei fogli restano solo i punti del fronte di Pareto. I punti dominati sono nel foglio Esclusi, con l’ID del punto che li domina; gli altri esclusi sono elencati con il motivo.
A8: • Righe evidenziate in giallo (fogli AMD – LUT, AMD – slice, Intel, HLS): sottoinsieme dei punti del fronte scelto per il confronto diretto, con il criterio scritto sotto il titolo del foglio. Le altre righe restano sul fronte come contesto.
A9: • Colonne: solo grandezze confrontabili — area dichiarata (e FF), Fmax, cicli per blocco c, TP e TP/area. Per SHA-3 tutti i valori si riferiscono a SHA3-256.
A10: • Lavoro: [n] = numero del riferimento nel foglio Fonti (cliccabile). La variante del design è nella colonna Architettura.
A11: • Il foglio xck26 (KV260) riporta per intero le risintesi dei core di riferimento e il nostro acceleratore: non è filtrato. Il foglio IP commerciali contiene dati di datasheet, non filtrati.
A12: • Colori: BLU = valore dichiarato dagli autori (o misurato da noi); NERO = formula, cioè valore ricalcolato da noi (equivale al simbolo * del report).
A13: • Simboli: † accanto al TP = dato da usare con cautela; il motivo è nel commento della cella (triangolo rosso, visibile al passaggio del mouse). n.d. = non dichiarato; – = non applicabile; ⏳ = da aggiornare.
... A29: Costanti
A30: Nome | B30: Valore | C30: Descrizione
A31: R_ASCON | B31: 64 | C31: rate Ascon-Hash (bit)
A32: R_256 | B32: 1088 | C32: rate SHA3-256 (bit)
A33: A10_GX1150_ALM | B33: 427200 | C33: ALM dell’Arria 10 GX 1150 (Bensalem et al.: VB = 85 426 ALM = 20 %)

Sheet AMD – LUT
A1: AMD, area dichiarata in LUT — punti del fronte di Pareto.
A2: Righe evidenziate: (1) stessa classe del nostro core — architetture iterative, al più 1 round per ciclo, senza unrolling né pipelining; (2) una sola edizione per benchmark ripetuto (GMU: Round 2, che dichiara c).
A4: ID | B4: Algoritmo | C4: Lavoro | D4: Famiglia | E4: Architettura | F4: Area dichiarata | G4: Unità | H4: FF | I4: Fmax (MHz) | J4: c (cicli/blocco) | K4: TP (Mbps) | L4: TP/area (kbps/unità)
A5: A09 | B5: Ascon-Hash | C5: [6] | D5: Spartan-6 | E5: 1 r/c, include AEAD (c = 15 per blocco hash) | F5: 2188 | G5: LUT | H5: n.d. | I5: 158.9 | J5: 15 | K5: =R_ASCON*I5/J5 -> 677.97333 | L5: =K5/F5*1000 -> 309.85984
A6: A01 | B6: Ascon-Hash | C6: [4] | D6: Artix-7 | E6: Hash + Hasha | F6: 1083 | G6: LUT | H6: 681 | I6: 200 | J6: 25 | K6: =R_ASCON*I6/J6 -> 512 | L6: =K6/F6*1000 -> 472.76085
A7: A02 | B7: Ascon-Hash | C7: [2] | D7: Artix-7 | E7: 1 r/c, include AEAD — GMU2-x1 | F7: 1315 | G7: LUT | H7: 863 | I7: 253 | K7: 1247 | L7: =K7/F7*1000 -> 948.28897
A8: A03 | B8: Ascon-Hash | C8: [1] | D8: Artix-7 | E8: 1 r/c, include AEAD — GMU2-v1h | F8: 1375 | G8: LUT | H8: 862 | I8: 276 | J8: 13 | K8: =R_ASCON*I8/J8 -> 1358.7692 | L8: =K8/F8*1000 -> 988.1958
A9: A04 | B9: Ascon-Hash | C9: [2] | D9: Artix-7 | E9: 2 r/c, include AEAD — GMU2-x2 | F9: 2082 | G9: LUT | H9: 864 | I9: 220 | K9: 2009 | L9: =K9/F9*1000 -> 964.93756
A10: A05 | B10: Ascon-Hash | C10: [1] | D10: Artix-7 | E10: 2 r/c, include AEAD — GMU2-v2h | F10: 2126 | G10: LUT | H10: 861 | I10: 234 | J10: 7 | K10: =R_ASCON*I10/J10 -> 2139.4286 | L10: =K10/F10*1000 -> 1006.3164
A11: A06 | B11: Ascon-Hash | C11: [3] | D11: Virtex-7 | E11: 1 r/c, solo hash — x1 | F11: 773 | G11: LUT | H11: n.d. | I11: 272.03 | J11: 12 | K11: =R_ASCON*I11/J11 -> 1450.8267 | L11: =K11/F11*1000 -> 1876.878
A12: A07 | B12: Ascon-Hash | C12: [3] | D12: Virtex-7 | E12: 2 r/c, solo hash — x2 | F12: 1290 | G12: LUT | H12: n.d. | I12: 224.56 | J12: 6 | K12: =R_ASCON*I12/J12 -> 2395.3067 | L12: =K12/F12*1000 -> 1856.8269
A13: A08 | B13: Ascon-Hash | C13: [3] | D13: Virtex-7 | E13: 4 r/c, solo hash — x4 | F13: 2550 | G13: LUT | H13: n.d. | I13: 162.68 | J13: 3 | K13: =R_ASCON*I13/J13 -> 3470.5067 | L13: =K13/F13*1000 -> 1360.983
A14: S01 | B14: SHA3-256 | C14: [7] | D14: Virtex-6 | E14: compatto, per lane | F14: 519 | G14: LUT | H14: 429 | I14: 250 | J14: 2137 | K14: =R_256*I14/J14 -> 127.28124 | L14: =K14/F14*1000 -> 245.24323
A15: S02 | B15: SHA3-256 | C15: [1] | D15: Artix-7 | E15: ripiegato ×8, senza padding | F15: 1263 | G15: LUT | H15: 277 | I15: 195 | J15: 233 | K15: =R_256*I15/J15 -> 910.55794 | L15: =K15/F15*1000 -> 720.94849
A16: S03 | B16: SHA3-256 | C16: [8] | D16: Artix-7 | E16: 1 r/c, solo permutazione Keccak-p[1600,24] | F16: 2970 | G16: LUT | H16: 1607 | I16: 244.31 | J16: 25 | K16: =R_256*I16/J16 -> 10632.371 | L16: =K16/F16*1000 -> 3579.923
A17: S04 | B17: SHA3-256 | C17: [8] | D17: Kintex-7 | E17: 1 r/c, solo permutazione Keccak-p[1600,24] | F17: 2970 | G17: LUT | H17: 1607 | I17: 313.47 | J17: 25 | K17: =R_256*I17/J17 -> 13642.214 | L17: =K17/F17*1000 -> 4593.3382

Sheet AMD – slice
A1: AMD, area dichiarata in slice — punti del fronte di Pareto. Nessun lavoro Ascon-Hash dichiara l’area in slice.
A2: Righe evidenziate: (1) stessa classe del nostro core — architetture iterative, al più 1 round per ciclo, senza unrolling né pipelining; (2) una sola edizione per benchmark ripetuto (Sideris et al.: JCEN 2024); (3) solo famiglie 7-series (Artix-7, Kintex-7, Virtex-7), le più vicine alla xck26: CLB da 8 LUT6 e 16 FF come l’UltraScale+.
A4: ID | B4: Algoritmo | C4: Lavoro | D4: Famiglia | E4: Architettura | F4: Area dichiarata | G4: Unità | H4: FF | I4: Fmax (MHz) | J4: c (cicli/blocco) | K4: TP (Mbps) | L4: TP/area (kbps/unità)
A5: S71 | B5: SHA3-256 | C5: [18] | D5: Spartan-3 | E5: compatto (lightweight), BRAM | F5: 627 | G5: slice | H5: n.d. | I5: =1000/8.9 -> 112.35955 | K5: 32.5 | L5: =K5/F5*1000 -> 51.834131
A6: S70 | B6: SHA3-256 | C6: [18] | D6: Spartan-3 | E6: compatto (lightweight), solo logica | F6: 766 | G6: slice | H6: n.d. | I6: =1000/9.83 -> 101.7294 | K6: 46.2 | L6: =K6/F6*1000 -> 60.313316
A7: S10 | B7: SHA3-256 | C7: [11] | D7: Spartan-3 | E7: 1 r/c + interfaccia 64 bit (Keccak 2014) | F7: 3632 | G7: slice | H7: n.d. | I7: 95.45 | J7: 41 | K7: =R_256*I7/J7 -> 2532.9171 | L7: =K7/F7*1000 -> 697.38906
A8: S30 | B8: SHA3-256 | C8: [13] | D8: Virtex-4 | E8: 1 r/c — senza pipeline | F8: 2365 | G8: slice | H8: n.d. | I8: 273 | J8: 24 | K8: =R_256*I8/J8 -> 12376 | L8: =K8/F8*1000 -> 5232.981
A9: S75 | B9: SHA3-256 | C9: [18] | D9: Virtex-5 | E9: compatto (lightweight), BRAM | F9: 159 | G9: slice | H9: n.d. | I9: =1000/4.04 -> 247.52475 | K9: 71.6 | L9: =K9/F9*1000 -> 450.31447
A10: S74 | B10: SHA3-256 | C10: [18] | D10: Virtex-5 | E10: compatto (lightweight), solo logica | F10: 275 | G10: slice | H10: n.d. | I10: =1000/3.85 -> 259.74026 | K10: 118.1 | L10: =K10/F10*1000 -> 429.45455
A11: S42 | B11: SHA3-256 | C11: [15] | D11: Virtex-5 | E11: ripiegato FF=4 | F11: 476 | G11: slice | H11: n.d. | I11: 200 | J11: 96 | K11: =R_256*I11/J11 -> 2266.6667 | L11: =K11/F11*1000 -> 4761.9048
A12: S90 | B12: SHA3-256 | C12: [20] | D12: Virtex-5 | E12: 1 r/c — 24 cicli | F12: 868 | G12: slice | H12: n.d. | I12: 347.49 | J12: 24 | K12: =R_256*I12/J12 -> 15752.88 | L12: =K12/F12*1000 -> 18148.479
A13: S91 | B13: SHA3-256 | C13: [20] | D13: Virtex-5 | E13: 2 r/c (unrolling ×2) — 12 cicli | F13: 1112 | G13: slice | H13: n.d. | I13: 203.28 | J13: 12 | K13: =R_256*I13/J13 -> 18430.72 | L13: =K13/F13*1000 -> 16574.388
A14: SA0 | B14: SHA3-256 | C14: [21] | D14: Virtex-5 | E14: unrolling + pipelining | F14: 1186 | G14: slice | H14: n.d. | I14: 272.41 | K14: 24699 | L14: =K14/F14*1000 -> 20825.464
A15: S72 | B15: SHA3-256 | C15: [18] | D15: Spartan-6 | E15: compatto (lightweight), solo logica | F15: 113 | G15: slice | H15: n.d. | I15: =1000/4.95 -> 202.0202 | K15: 91.8 | L15: =K15/F15*1000 -> 812.38938
A16: SD2 | B16: SHA3-256 | C16: [29] | D16: Spartan-6 | E16: 1 r/c (LUT6 con INIT condiviso) | F16: 1162 | G16: slice | H16: n.d. | I16: 111.73 | J16: 24 | K16: =R_256*I16/J16 -> 5065.0933 | L16: =K16/F16*1000 -> 4358.9443
A17: S76 | B17: SHA3-256 | C17: [18] | D17: Virtex-6 | E17: compatto (lightweight), solo logica | F17: 106 | G17: slice | H17: n.d. | I17: =1000/3.34 -> 299.4012 | K17: 136 | L17: =K17/F17*1000 -> 1283.0189
A18: S92 | B18: SHA3-256 | C18: [20] | D18: Virtex-6 | E18: 1 r/c — 24 cicli | F18: 946 | G18: slice | H18: n.d. | I18: 438.49 | J18: 24 | K18: =R_256*I18/J18 -> 19878.213 | L18: =K18/F18*1000 -> 21012.911
A19: S93 | B19: SHA3-256 | C19: [20] | D19: Virtex-6 | E19: 2 r/c (unrolling ×2) — 12 cicli | F19: 1287 | G19: slice | H19: n.d. | I19: 347.84 | J19: 12 | K19: =R_256*I19/J19 -> 31537.493 | L19: =K19/F19*1000 -> 24504.657
A20: S96 | B20: SHA3-256 | C20: [20] | D20: Artix-7 | E20: 1 r/c — 24 cicli | F20: 902 | G20: slice | H20: n.d. | I20: 397.41 | J20: 24 | K20: =R_256*I20/J20 -> 18015.92 | L20: =K20/F20*1000 -> 19973.304
A21: S97 | B21: SHA3-256 | C21: [20] | D21: Artix-7 | E21: 2 r/c (unrolling ×2) — 12 cicli | F21: 1184 | G21: slice | H21: n.d. | I21: 254.46 | J21: 12 | K21: =R_256*I21/J21 -> 23071.04 | L21: =K21/F21*1000 -> 19485.676
A22: SD3 | B22: SHA3-256 | C22: [29] | D22: Kintex-7 | E22: 1 r/c (LUT6 con INIT condiviso) | F22: 1185 | G22: slice | H22: n.d. | I22: 213.17 | J22: 24 | K22: =R_256*I22/J22 -> 9663.7067 | L22: =K22/F22*1000 -> 8155.0267
A23: S94 | B23: SHA3-256 | C23: [20] | D23: Virtex-7 | E23: 1 r/c — 24 cicli | F23: 1094 | G23: slice | H23: n.d. | I23: 498.27 | J23: 24 | K23: =R_256*I23/J23 -> 22588.24 | L23: =K23/F23*1000 -> 20647.386
A24: S95 | B24: SHA3-256 | C24: [20] | D24: Virtex-7 | E24: 2 r/c (unrolling ×2) — 12 cicli | F24: 1375 | G24: slice | H24: n.d. | I24: 378.73 | J24: 12 | K24: =R_256*I24/J24 -> 34338.187 | L24: =K24/F24*1000 -> 24973.227
A25: SA2 | B25: SHA3-256 | C25: [21] | D25: Virtex-7 | E25: unrolling + pipelining | F25: 1452 | G25: slice | H25: n.d. | I25: 396.28 | K25: 35929 | L25: =K25/F25*1000 -> 24744.49

Sheet Intel
A1: Intel (Altera), area in ALM / ALUT / LE / "slice" non definita — solo punti del fronte di Pareto, separati per unità.
A2: Righe evidenziate: (1) stessa classe del nostro core — architetture iterative, al più 1 round per ciclo, senza unrolling né pipelining; (2) una sola edizione per benchmark ripetuto; (3) solo famiglie a 28 nm o più recenti (Cyclone V, Stratix V, Arria 10), la stessa generazione della 7-series. Sideris et al. (Arria 10) esclusi dal criterio (1): pipeline a 2 stadi, e area in "slice" non definita su Intel. Cyclone 10 LP (GMU Round 2) esclusa dal criterio (3): stessa architettura LE della Cyclone IV.
A4: ID | B4: Algoritmo | C4: Lavoro | D4: Famiglia | E4: Architettura | F4: Area dichiarata | G4: Unità | H4: FF | I4: Fmax (MHz) | J4: c (cicli/blocco) | K4: TP (Mbps) | L4: TP/area (kbps/unità)
A5: G10 | B5: Ascon-Hash | C5: [1] | D5: Cyclone 10 LP | E5: 1 r/c (basic iterative), include AEAD — GMU2-v1h | F5: 2415 | G5: LE | H5: 867 | I5: 175.6 | J5: 13 | K5: =R_ASCON*I5/J5 -> 864.49231 | L5: =K5/F5*1000 -> 357.96783
A6: G11 | B6: Ascon-Hash | C6: [1] | D6: Cyclone 10 LP | E6: 2 r/c (2× unrolled), include AEAD — GMU2-v2h | F6: 3215 | G6: LE | H6: 865 | I6: 134.8 | J6: 7 | K6: =R_ASCON*I6/J6 -> 1232.4571 | L6: =K6/F6*1000 -> 383.34592
A7: A20 | B7: Ascon-Hash | C7: [6] | D7: Cyclone V | E7: 1 r/c, include AEAD (c = 15 per blocco hash) | F7: 1064 | G7: ALM | H7: n.d. | I7: 210.5 | J7: 15 | K7: =R_ASCON*I7/J7 -> 898.13333 | L7: =K7/F7*1000 -> 844.11028
A8: I20 | B8: SHA3-256 | C8: [18] | D8: Cyclone II | E8: compatto (lightweight), BRAM | F8: 996 | G8: LE | H8: n.d. | I8: =1000/5.48 -> 182.48175 | K8: 52.7 | L8: =K8/F8*1000 -> 52.911647
A9: I21 | B9: SHA3-256 | C9: [18] | D9: Cyclone II | E9: compatto (lightweight), solo logica | F9: 6247 | G9: LE | H9: n.d. | I9: =1000/8.49 -> 117.78563 | K9: 53.5 | L9: =K9/F9*1000 -> 8.5641108
A10: I01 | B10: SHA3-256 | C10: [11] | D10: Cyclone III | E10: 1 r/c + interfaccia 64 bit (Keccak 2014) | F10: 5636 | G10: LE | H10: n.d. | I10: 53.23 | J10: 41 | K10: =R_256*I10/J10 -> 1412.5424 | L10: =K10/F10*1000 -> 250.62854
A11: I12 | B11: SHA3-256 | C11: [12] | D11: Cyclone III | E11: 1 r/c — originale | F11: 5761 | G11: LE | H11: 2641 | I11: 137.51 | J11: 24 | K11: =R_256*I11/J11 -> 6233.7867 | L11: =K11/F11*1000 -> 1082.0668
A12: I02 | B12: SHA3-256 | C12: [11] | D12: Cyclone IV | E12: 1 r/c + interfaccia 64 bit (Keccak 2014) | F12: 5636 | G12: LE | H12: n.d. | I12: 51.76 | J12: 41 | K12: =R_256*I12/J12 -> 1373.5337 | L12: =K12/F12*1000 -> 243.70718
A13: G19 | B13: SHA3-256 | C13: [1] | D13: Cyclone 10 LP | E13: ripiegato ×8, senza padding — SHA3-v1 | F13: 5417 | G13: LE | H13: 3444 | I13: 84.5 | J13: 233 | K13: =R_256*I13/J13 -> 394.57511 | L13: =K13/F13*1000 -> 72.840153
A14: I03 | B14: SHA3-256 | C14: [11] | D14: Cyclone V | E14: 1 r/c + interfaccia 64 bit (Keccak 2014) | F14: 2679 | G14: ALM | H14: n.d. | I14: 60.11 | J14: 41 | K14: =R_256*I14/J14 -> 1595.1141 | L14: =K14/F14*1000 -> 595.41402
A15: I30 | B15: SHA3-256 | C15: [30] | D15: Cyclone V | E15: 1 r/c, ingresso 128 bit/ciclo — KECCAK-CORE | F15: 3415 | G15: ALM | H15: n.d. | I15: 271.69 | K15: 11000 | L15: =K15/F15*1000 -> 3221.0835
A16: I00 | B16: SHA3-256 | C16: [11] | D16: Arria II | E16: 1 r/c + interfaccia 64 bit (Keccak 2014) | F16: 2980 | G16: ALM | H16: n.d. | I16: 211.24 | J16: 41 | K16: =R_256*I16/J16 -> 5605.5883 | L16: =K16/F16*1000 -> 1881.0699
A17: I40 | B17: SHA3-256 | C17: [22] | D17: Arria 10 | E17: pipeline a 2 stadi (VHDL) | F17: 1422 | G17: slice (n.d.) | H17: n.d. | I17: 498.62 | J17: 48 | K17: =R_256*I17/J17 -> 11302.053 | L17: =K17/F17*1000 -> 7947.9981
A18: I41 | B18: SHA3-256 | C18: [23] | D18: Arria 10 | E18: pipeline a 2 stadi (VHDL) | F18: 2682 | G18: slice (n.d.) | H18: n.d. | I18: 432 | J18: 18 | K18: =R_256*I18/J18 -> 26112 | L18: =K18/F18*1000 -> 9736.0179
A19: I42 | B19: SHA3-256 | C19: [23] | D19: Arria 10 | E19: pipeline a 2 stadi (VHDL) — con FPH-2 | F19: 2764 | G19: slice (n.d.) | H19: n.d. | I19: 472 | J19: 14 | K19: =R_256*I19/J19 -> 36681.143 | L19: =K19/F19*1000 -> 13271.036
A20: I04 | B20: SHA3-256 | C20: [11] | D20: Stratix II | E20: 1 r/c + interfaccia 64 bit (Keccak 2014) | F20: 3732 | G20: ALM | H20: n.d. | I20: 86.96 | J20: 41 | K20: =R_256*I20/J20 -> 2307.6215 | L20: =K20/F20*1000 -> 618.33373
A21: I05 | B21: SHA3-256 | C21: [11] | D21: Stratix III | E21: 1 r/c + interfaccia 64 bit (Keccak 2014) | F21: 3738 | G21: ALM | H21: n.d. | I21: 261.85 | J21: 41 | K21: =R_256*I21/J21 -> 6948.6049 | L21: =K21/F21*1000 -> 1858.9098
A22: I11 | B22: SHA3-256 | C22: [12] | D22: Stratix III | E22: 1 r/c — originale | F22: 4304 | G22: ALUT | H22: 2641 | I22: 230.57 | J22: 24 | K22: =R_256*I22/J22 -> 10452.507 | L22: =K22/F22*1000 -> 2428.5564
A23: I10 | B23: SHA3-256 | C23: [12] | D23: Stratix III | E23: 3 round in 2 cicli — srotolato | F23: 14402 | G23: ALUT | H23: 2653 | I23: 212.49 | J23: 16 | K23: =R_256*I23/J23 -> 14449.32 | L23: =K23/F23*1000 -> 1003.2857
A24: I06 | B24: SHA3-256 | C24: [11] | D24: Stratix IV | E24: 1 r/c + interfaccia 64 bit (Keccak 2014) | F24: 3675 | G24: ALM | H24: n.d. | I24: 278.47 | J24: 41 | K24: =R_256*I24/J24 -> 7389.6429 | L24: =K24/F24*1000 -> 2010.7872
A25: I07 | B25: SHA3-256 | C25: [11] | D25: Stratix V | E25: 1 r/c + interfaccia 64 bit (Keccak 2014) | F25: 3647 | G25: ALM | H25: n.d. | I25: 328.62 | J25: 41 | K25: =R_256*I25/J25 -> 8720.4527 | L25: =K25/F25*1000 -> 2391.1304

Sheet HLS
A1: Implementazioni HLS pubblicate — fronte di Pareto per famiglia; la libreria AMD (device n.d.) non è filtrabile.
A2: Righe evidenziate: (1) stessa classe del nostro core — architetture iterative, al più 1 round per ciclo, senza unrolling né pipelining; (2) una sola edizione per benchmark ripetuto; (3) famiglia dichiarata, 7-series / 28 nm o più recente. Non evidenziati: Bensalem et al. (architettura e c non dichiarati, criterio 1 non verificabile) e AMD Vitis Security Library (device non dichiarato, criterio 3 non verificabile; in attesa della risintesi sulla xck26).
A4: ID | B4: Algoritmo | C4: Lavoro | D4: Famiglia | E4: Architettura | F4: Area dichiarata | G4: Unità | H4: FF | I4: Fmax (MHz) | J4: c (cicli/blocco) | K4: TP (Mbps) | L4: TP/area (kbps/unità)
A5: H01 | B5: SHA3-256 | C5: [9] | D5: Virtex-7 | E5: HLS (C) | F5: 6234 | G5: LUT | H5: 2597 | I5: 162.31 | J5: 49 | K5: =R_256*I5/J5 -> 3603.9445 | L5: =K5/F5*1000 -> 578.11108
A6: H04 | B6: SHA3-256 | C6: [31] | D6: Arria 10 | E6: HLS (Intel FPGA SDK for OpenCL), dati in memoria locale — kernel VLU | F6: =0.13*A10_GX1150_ALM -> 55536 | G6: ALM | H6: n.d. | I6: 312 | K6: 22360 | L6: =K6/F6*1000 -> 402.62172
A7: H02 | B7: SHA3-256 | C7: [10] | D7: n.d. | E7: HLS (C++), libreria vendor — SHA3-256 | F7: 44975 | G7: LUT | H7: 36787 | I7: 306.65 | J7: 1104 | K7: =R_256*I7/J7 -> 302.2058 | L7: =K7/F7*1000 -> 6.7194174

Sheet Altre architetture
A1: Altre architetture — vendor diversi da AMD e Intel. Dati non confrontabili direttamente con gli altri fogli (LUT a 4 ingressi): contesto. Tabella 1: fronte di Pareto su Lattice ECP5 (GMU Round 2).
A2: Righe evidenziate: (1) stessa classe del nostro core — architetture iterative, al più 1 round per ciclo, senza unrolling né pipelining; (2) una sola edizione per benchmark ripetuto. Nessun criterio sulla famiglia: c’è una sola famiglia con dati completi.
A4: ID | B4: Algoritmo | C4: Lavoro | D4: Famiglia | E4: Architettura | F4: Area dichiarata | G4: Unità | H4: FF | I4: Fmax (MHz) | J4: c (cicli/blocco) | K4: TP (Mbps) | L4: TP/area (kbps/unità)
A5: L13 | B5: Ascon-Hash | C5: [1] | D5: ECP5 | E5: 1 r/c (basic iterative), include AEAD Ascon-128 — Graz-v1 | F5: 2544 | G5: LUT4 | H5: 676 | I5: 59.3 | J5: 14 | K5: =R_ASCON*I5/J5 -> 271.08571 | L5: =K5/F5*1000 -> 106.55885
A6: L14 | B6: Ascon-Hash | C6: [1] | D6: ECP5 | E6: 1 r/c (basic iterative), include AEAD Ascon-128a — Graz-v2 | F6: 2603 | G6: LUT4 | H6: 674 | I6: 64 | J6: 14 | K6: =R_ASCON*I6/J6 -> 292.57143 | L6: =K6/F6*1000 -> 112.39778
A7: L10 | B7: Ascon-Hash | C7: [1] | D7: ECP5 | E7: 1 r/c (basic iterative), include AEAD — GMU2-v1h | F7: 2928 | G7: LUT4 | H7: 864 | I7: 110.1 | J7: 13 | K7: =R_ASCON*I7/J7 -> 542.03077 | L7: =K7/F7*1000 -> 185.1198
A8: L11 | B8: Ascon-Hash | C8: [1] | D8: ECP5 | E8: 2 r/c (2× unrolled), include AEAD — GMU2-v2h | F8: 3764 | G8: LUT4 | H8: 862 | I8: 89.2 | J8: 7 | K8: =R_ASCON*I8/J8 -> 815.54286 | L8: =K8/F8*1000 -> 216.6692
A9: L20 | B9: SHA3-256 | C9: [1] | D9: ECP5 | E9: ripiegato ×8, senza padding — SHA3-v1 | F9: 1804 | G9: LUT4 | H9: 249 | I9: 90.3 | J9: 233 | K9: =R_256*I9/J9 -> 421.65837 | L9: =K9/F9*1000 -> 233.73524
A11: Tabella 2 — Stesso RTL su tre famiglie di tre vendor (GMU Round 2, stesso flusso di benchmark)
A12: Valori letti dalle righe dei fogli AMD – LUT, Intel e Altre architetture (formule). c è lo stesso sulle tre famiglie, quindi il rapporto dei TP coincide con il rapporto delle Fmax.
A13: Design | B13: Algoritmo | C13: LUT Artix-7 | D13: LE Cyclone 10 LP | E13: LUT4 ECP5 | F13: LE / LUT | G13: LUT4 / LUT | H13: TP Artix-7 (Mbps) | I13: TP Cyclone 10 LP (Mbps) | J13: TP ECP5 (Mbps) | K13: TP Artix-7 / Cyclone 10 LP | L13: TP Artix-7 / ECP5
A14: GMU Round 2, GMU2-v1h | B14: Ascon-Hash | C14: ='AMD – LUT'!F8 -> 1375 | D14: =Intel!F5 -> 2415 | E14: ='Altre architetture'!F7 -> 2928 | F14: =D14/C14 -> 1.7563636 | G14: =E14/C14 -> 2.1294545 | H14: ='AMD – LUT'!K8 -> 1358.7692 | I14: =Intel!K5 -> 864.49231 | J14: ='Altre architetture'!K7 -> 542.03077 | K14: =H14/I14 -> 1.571754 | L14: =H14/J14 -> 2.506812
A15: GMU Round 2, GMU2-v2h | B15: Ascon-Hash | C15: ='AMD – LUT'!F10 -> 2126 | D15: =Intel!F6 -> 3215 | E15: ='Altre architetture'!F8 -> 3764 | F15: =D15/C15 -> 1.5122295 | G15: =E15/C15 -> 1.770461 | H15: ='AMD – LUT'!K10 -> 2139.4286 | I15: =Intel!K6 -> 1232.4571 | J15: ='Altre architetture'!K8 -> 815.54286 | K15: =H15/I15 -> 1.735905 | L15: =H15/J15 -> 2.6233184
A16: GMU Round 2, SHA3-v1 | B16: SHA3-256 | C16: ='AMD – LUT'!F15 -> 1263 | D16: =Intel!F13 -> 5417 | E16: ='Altre architetture'!F9 -> 1804 | F16: =D16/C16 -> 4.2889945 | G16: =E16/C16 -> 1.4283452 | H16: ='AMD – LUT'!K15 -> 910.55794 | I16: =Intel!K13 -> 394.57511 | J16: ='Altre architetture'!K9 -> 421.65837 | K16: =H16/I16 -> 2.3076923 | L16: =H16/J16 -> 2.1594684
A17: Medie GMU su tutti i design di Round 2 (testo, sez. 5.1): LE Cyclone 10 LP / LUT Artix-7 = 1.88; LUT ECP5 / LUT Artix-7 = 1.77; Fmax Artix-7 / Cyclone 10 LP = 1.72; Fmax Artix-7 / ECP5 = 2.59.
A18: SHA3-v1 su Cyclone 10 LP: LE 4.29× e FF 12.43× rispetto ad Artix-7, perché lo stato non può stare in RAM distribuita (vedi il commento della cella TP nel foglio Intel).
A20: Tabella 3 — IP commerciali su Lattice e Microchip (datasheet del vendor, solo area: Fmax e TP non dichiarati)
A21: ID | B21: Algoritmo | C21: IP | D21: Famiglia | E21: Configurazione | F21: Area | G21: Unità
A22: C20 | B22: SHA-3 | C22: Xiphera XIP3030C (compatto) | D22: ECP5 | E22: SHA-3 + SHAKE + cSHAKE | F22: 1278 | G22: LUT4
A23: C21 | B23: SHA-3 | C23: Xiphera XIP3030C (compatto) | D23: CertusPro-NX | E23: SHA-3 + SHAKE + cSHAKE | F23: 1245 | G23: LUT4
A24: C22 | B24: SHA-3 | C24: Xiphera XIP3030C (compatto) | D24: PolarFire | E24: SHA-3 + SHAKE + cSHAKE | F24: 1853 | G24: LUT4
A25: C23 | B25: Ascon-Hash | C25: Xiphera XIP2201B (bilanciato) | D25: Lattice (n.d.) | E25: AEAD + Hash + XOF | F25: 4665 | G25: LUT4

Sheet xck26 (KV260)
A1: xck26-sfvc784-2LV-c (KV260): risintesi dei core di riferimento (Vivado 2025.1.1, OOC, post-route, prestazione di picco) e nostro acceleratore (Vitis HLS 2025.1, vincolo 10 ns, post-route). Non filtrato.
A2: ID | B2: Algoritmo | C2: Core | D2: LUT | E2: FF | F2: CLB (= slice) | G2: Fmax (MHz) | H2: c (cicli/blocco) | I2: TP (Mbps) | J2: TP/LUT (kbps/LUT)
A3: K01 | B3: Ascon-Hash | C3: ascon-verilog v4, solo hash | D3: 1330 | E3: 336 | F3: 192 | G3: 547.3 | H3: 13 | I3: =R_ASCON*G3/H3 -> 2694.4 | J3: =IF(ISNUMBER(I3),I3/D3*1000,"") -> 2025.8647
A4: K02 | B4: Ascon-Hash | C4: GMU2 Ascon-128 x1 (BlueLight) | D4: 1327 | E4: 839 | F4: 203 | G4: 535.3 | H4: 13 | I4: =R_ASCON*G4/H4 -> 2635.3231 | J4: =IF(ISNUMBER(I4),I4/D4*1000,"") -> 1985.9255
A5: K03 | B5: SHA3-256 | C5: Keccak team high-speed v3.1, SHA3-256 | D5: 4444 | E5: 2708 | F5: 655 | G5: 401.6 | H5: 24 | I5: =R_256*G5/H5 -> 18205.867 | J5: =IF(ISNUMBER(I5),I5/D5*1000,"") -> 4096.7297
A6: K05 | B6: Ascon-Hash | C6: Nostro: Ascon standalone | D6: 1200 | E6: 744 | F6: 210 | G6: =1000/4.722 -> 211.77467 | H6: ⏳ | I6: ⏳ | J6: =IF(ISNUMBER(I6),I6/D6*1000,"")
A7: K06 | B7: SHA3-256 | C7: Nostro: SHA-3 standalone | D7: 2214 | E7: 1551 | F7: 474 | G7: =1000/6.023 -> 166.03022 | H7: ⏳ | I7: ⏳ | J7: =IF(ISNUMBER(I7),I7/D7*1000,"")
A8: K07 | B8: Ascon-Hash + SHA3-256 | C8: Nostro: ibrido | D8: 3281 | E8: 2215 | F8: 667 | G8: =1000/6.169 -> 162.10083 | H8: ⏳ | I8: ⏳ | J8: =IF(ISNUMBER(I8),I8/D8*1000,"")
A10: Fonti dei valori: sota-refs/ref_*/summary.csv (risintesi) e logs/hls_run_impl.log dei componenti Vitis (nostro acceleratore). Flusso, vincolo, periodo post-route e RAMB18 nel commento della cella Core.
A11: SHA-3 confrontato solo su SHA3-256: la risintesi SHA3-512 dello stesso core Keccak team (K04) non è riportata.

Sheet IP commerciali
A1: IP commerciali su AMD e Intel (datasheet del vendor): non peer-reviewed, non filtrati. TP calcolato solo dove il vendor dichiara i bit per ciclo. IP su Lattice e Microchip: foglio Altre architetture.
A2: ID | B2: Algoritmo | C2: IP | D2: Famiglia | E2: Configurazione | F2: Area | G2: Unità | H2: Fmax (MHz) | I2: bit/ciclo dichiarati | J2: TP (Mbps) = bit/ciclo × f | K2: TP/area (kbps/unità)
A3: C01 | B3: SHA-3 | C3: CAST SHA-3 | D3: Spartan-7 | E3: 64 bit, 1 round/ciclo, 1 buffer | F3: 4767 | G3: LUT | H3: 125 | J3: n.d. | K3: n.d.
A4: C02 | B4: SHA-3 | C4: CAST SHA-3 | D4: Artix-7 | E4: 64 bit, 1 round/ciclo, 1 buffer | F4: 4772 | G4: LUT | H4: 150 | J4: n.d. | K4: n.d.
A5: C03 | B5: SHA-3 | C5: CAST SHA-3 | D5: UltraScale+ | E5: 64 bit, 1 round/ciclo, 1 buffer | F5: 4808 | G5: LUT | H5: 375 | J5: n.d. | K5: n.d.
A6: C04 | B6: SHA-3 | C6: CAST SHA-3 | D6: UltraScale+ | E6: 128 bit, 2 round/ciclo, 2 buffer | F6: 10340 | G6: LUT | H6: 200 | J6: n.d. | K6: n.d.
A7: C05 | B7: SHA-3 | C7: CAST SHA-3 | D7: UltraScale+ | E7: 512 bit, 4 round/ciclo, 2 buffer | F7: 20672 | G7: LUT | H7: 100 | J7: n.d. | K7: n.d.
A8: C06 | B8: SHA-3 | C8: CAST SHA-3 | D8: Cyclone V | E8: 32 bit, 1 round/ciclo, 0 buffer | F8: 3291 | G8: ALM | H8: 100 | J8: n.d. | K8: n.d.
A9: C07 | B9: SHA-3 | C9: CAST SHA-3 | D9: Arria 10 | E9: 64 bit, 1 round/ciclo, 1 buffer | F9: 3852 | G9: ALM | H9: 300 | J9: n.d. | K9: n.d.
A10: C08 | B10: SHA-3 | C10: CAST SHA-3 | D10: Agilex | E10: 64 bit, 1 round/ciclo, 1 buffer | F10: 4087 | G10: ALM | H10: 500 | J10: n.d. | K10: n.d.
A11: C09 | B11: SHA-3 | C11: CAST SHA-3 | D11: Agilex | E11: 128 bit, 2 round/ciclo, 2 buffer | F11: 6537 | G11: ALM | H11: 250 | J11: n.d. | K11: n.d.
A12: C10 | B12: SHA-3 | C12: CAST SHA-3 | D12: Agilex | E12: 512 bit, 4 round/ciclo, 2 buffer | F12: 14228 | G12: ALM | H12: 125 | J12: n.d. | K12: n.d.
A13: C11 | B13: Ascon-Hash | C13: CAST ASCON-F | D13: Kintex-7 | E13: AEAD + Hash | F13: 1202 | G13: LUT | H13: 475 | I13: 5.3 | J13: =I13*H13 -> 2517.5 | K13: =J13/F13*1000 -> 2094.426
A14: C12 | B14: Ascon-Hash | C14: CAST ASCON-F | D14: UltraScale | E14: AEAD + Hash | F14: 1223 | G14: LUT | H14: 700 | I14: 5.3 | J14: =I14*H14 -> 3710 | K14: =J14/F14*1000 -> 3033.5241
A15: C13 | B15: Ascon-Hash | C15: CAST ASCON-F | D15: UltraScale+ | E15: AEAD + Hash | F15: 1211 | G15: LUT | H15: 900 | I15: 5.3 | J15: =I15*H15 -> 4770 | K15: =J15/F15*1000 -> 3938.8935
A16: C14 | B16: Ascon-Hash | C16: CAST ASCON-F | D16: Versal | E16: AEAD + Hash | F16: 1481 | G16: LUT | H16: 625 | I16: 5.3 | J16: =I16*H16 -> 3312.5 | K16: =J16/F16*1000 -> 2236.6644
A17: C15 | B17: Ascon-Hash | C17: CAST ASCON-F | D17: Agilex | E17: AEAD + Hash | F17: 1295 | G17: ALM | H17: 700 | I17: 5.3 | J17: =I17*H17 -> 3710 | K17: =J17/F17*1000 -> 2864.8649
A18: C16 | B18: Ascon-Hash | C18: CAST ASCON-F | D18: Arria 10 | E18: AEAD + Hash | F18: 1225 | G18: ALM | H18: 525 | I18: 5.3 | J18: =I18*H18 -> 2782.5 | K18: =J18/F18*1000 -> 2271.4286
A19: C17 | B19: Ascon-Hash | C19: CAST ASCON-F | D19: Cyclone V | E19: AEAD + Hash | F19: 1207 | G19: ALM | H19: 250 | I19: 5.3 | J19: =I19*H19 -> 1325 | K19: =J19/F19*1000 -> 1097.763
A20: C18 | B20: Ascon-Hash | C20: CAST ASCON-F | D20: MAX 10 | E20: AEAD + Hash | F20: 2058 | G20: LE | H20: 175 | I20: 5.3 | J20: =I20*H20 -> 927.5 | K20: =J20/F20*1000 -> 450.68027
A21: C19 | B21: Ascon-Hash | C21: CAST ASCON-F | D21: Stratix V | E21: AEAD + Hash | F21: 1173 | G21: ALM | H21: 500 | I21: 5.3 | J21: =I21*H21 -> 2650 | K21: =J21/F21*1000 -> 2259.1645

Sheet Esclusi
A1: 1) Punti dominati nel proprio gruppo (stesso metodo, algoritmo, famiglia e unità). Stesse colonne dei fogli dati; ultima colonna: ID dei punti che li dominano.
A2: ID | B2: Algoritmo | C2: Lavoro | D2: Famiglia | E2: Architettura | F2: Area dichiarata | G2: Unità | H2: FF | I2: Fmax (MHz) | J2: c (cicli/blocco) | K2: TP (Mbps) | L2: TP/area (kbps/unità) | M2: Dominato da
A3: A11 | B3: Ascon-Hash | C3: [5] | D3: Artix-7 | E3: AEAD + Hash (4 modalità) | F3: 1548 | G3: LUT | H3: 1045 | I3: 244 | J3: 13 | K3: =R_ASCON*I3/J3 -> 1201.2308 | L3: =K3/F3*1000 -> 775.98887 | M3: A02, A03
A4: A12 | B4: Ascon-Hash | C4: [2] | D4: Artix-7 | E4: 1 r/c, include AEAD — x1 | F4: 2113 | G4: LUT | H4: 582 | I4: 205 | K4: 937 | L4: =K4/F4*1000 -> 443.44534 | M4: A02, A03, A04
A5: A10 | B5: Ascon-Hash | C5: [6] | D5: Artix-7 | E5: 1 r/c, include AEAD | F5: 2181 | G5: LUT | H5: n.d. | I5: 242 | J5: 15 | K5: =R_ASCON*I5/J5 -> 1032.5333 | L5: =K5/F5*1000 -> 473.42198 | M5: A02, A03, A04, A05
A6: A13 | B6: Ascon-Hash | C6: [2] | D6: Artix-7 | E6: 2 r/c, include AEAD — x2 | F6: 2967 | G6: LUT | H6: 588 | I6: 130 | K6: 1387 | L6: =K6/F6*1000 -> 467.47556 | M6: A04, A05
A7: G13 | B7: Ascon-Hash | C7: [1] | D7: Cyclone 10 LP | E7: 1 r/c (basic iterative), include AEAD Ascon-128 — Graz-v1 | F7: 2517 | G7: LE | H7: 775 | I7: 141.4 | J7: 14 | K7: =R_ASCON*I7/J7 -> 646.4 | L7: =K7/F7*1000 -> 256.81367 | M7: G10
A8: G14 | B8: Ascon-Hash | C8: [1] | D8: Cyclone 10 LP | E8: 1 r/c (basic iterative), include AEAD Ascon-128a — Graz-v2 | F8: 2634 | G8: LE | H8: 775 | I8: 143.3 | J8: 14 | K8: =R_ASCON*I8/J8 -> 655.08571 | L8: =K8/F8*1000 -> 248.70376 | M8: G10
A9: G18 | B9: Ascon-Hash | C9: [1] | D9: Cyclone 10 LP | E9: 1 r/c (basic iterative), include AEAD — VT-v2 | F9: 2695 | G9: LE | H9: 640 | I9: 172 | J9: 15 | K9: =R_ASCON*I9/J9 -> 733.86667 | L9: =K9/F9*1000 -> 272.30674 | M9: G10
A10: G15 | B10: Ascon-Hash | C10: [1] | D10: Cyclone 10 LP | E10: 2× unrolled, include AEAD — Graz-v3 | F10: 3716 | G10: LE | H10: 774 | I10: 109.7 | J10: 8 | K10: =R_ASCON*I10/J10 -> 877.6 | L10: =K10/F10*1000 -> 236.16792 | M10: G11
A11: G16 | B11: Ascon-Hash | C11: [1] | D11: Cyclone 10 LP | E11: 2× unrolled, include AEAD — Graz-v4 | F11: 3730 | G11: LE | H11: 774 | I11: 108.7 | J11: 8 | K11: =R_ASCON*I11/J11 -> 869.6 | L11: =K11/F11*1000 -> 233.13673 | M11: G11
A12: G12 | B12: Ascon-Hash | C12: [1] | D12: Cyclone 10 LP | E12: 3 r/c (3× unrolled), include AEAD — GMU2-v3h | F12: 4161 | G12: LE | H12: 867 | I12: 91.7 | J12: 5 | K12: =R_ASCON*I12/J12 -> 1173.76 | L12: =K12/F12*1000 -> 282.08604 | M12: G11
A13: G17 | B13: Ascon-Hash | C13: [1] | D13: Cyclone 10 LP | E13: 3× unrolled, include AEAD — Graz-v5 | F13: 4905 | G13: LE | H13: 775 | I13: 80.1 | J13: 6 | K13: =R_ASCON*I13/J13 -> 854.4 | L13: =K13/F13*1000 -> 174.1896 | M13: G10, G11
A14: L19 | B14: Ascon-Hash | C14: [1] | D14: ECP5 | E14: 1 r/c (basic iterative), include AEAD — VT-v2 | F14: 3041 | G14: LUT4 | H14: 557 | I14: 75.4 | J14: 15 | K14: =R_ASCON*I14/J14 -> 321.70667 | L14: =K14/F14*1000 -> 105.78976 | M14: L10
A15: L15 | B15: Ascon-Hash | C15: [1] | D15: ECP5 | E15: 2× unrolled, include AEAD — Graz-v3 | F15: 3305 | G15: LUT4 | H15: 674 | I15: 63.7 | J15: 8 | K15: =R_ASCON*I15/J15 -> 509.6 | L15: =K15/F15*1000 -> 154.19062 | M15: L10
A16: L16 | B16: Ascon-Hash | C16: [1] | D16: ECP5 | E16: 2× unrolled, include AEAD — Graz-v4 | F16: 3379 | G16: LUT4 | H16: 675 | I16: 61.9 | J16: 8 | K16: =R_ASCON*I16/J16 -> 495.2 | L16: =K16/F16*1000 -> 146.55223 | M16: L10
A17: L17 | B17: Ascon-Hash | C17: [1] | D17: ECP5 | E17: 3× unrolled, include AEAD — Graz-v5 | F17: 4646 | G17: LUT4 | H17: 876 | I17: 55.6 | J17: 6 | K17: =R_ASCON*I17/J17 -> 593.06667 | L17: =K17/F17*1000 -> 127.65103 | M17: L11
A18: L12 | B18: Ascon-Hash | C18: [1] | D18: ECP5 | E18: 3 r/c (3× unrolled), include AEAD — GMU2-v3h | F18: 4925 | G18: LUT4 | H18: 862 | I18: 61.2 | J18: 5 | K18: =R_ASCON*I18/J18 -> 783.36 | L18: =K18/F18*1000 -> 159.05787 | M18: L11
A19: L18 | B19: Ascon-Hash | C19: [1] | D19: ECP5 | E19: 4× unrolled, include AEAD — Graz-v6 | F19: 5346 | G19: LUT4 | H19: 675 | I19: 38.8 | J19: 5 | K19: =R_ASCON*I19/J19 -> 496.64 | L19: =K19/F19*1000 -> 92.899364 | M19: L10, L11
A20: S11 | B20: SHA3-256 | C20: [11] | D20: Virtex-4 | E20: 1 r/c + interfaccia 64 bit (Keccak 2014) | F20: 3622 | G20: slice | H20: n.d. | I20: 185.05 | J20: 41 | K20: =R_256*I20/J20 -> 4910.5951 | L20: =K20/F20*1000 -> 1355.7689 | M20: S30
A21: S31 | B21: SHA3-256 | C21: [13] | D21: Virtex-4 | E21: 1 r/c, pipeline esterna a 2 stadi | F21: 5494 | G21: slice | H21: n.d. | I21: 269 | J21: 24 | K21: =R_256*I21/J21 -> 12194.667 | L21: =K21/F21*1000 -> 2219.6335 | M21: S30
A22: S80 | B22: SHA3-256 | C22: [19] | D22: Virtex-5 | E22: 1 r/c (versione base) — 1 stadio | F22: 935 | G22: slice | H22: n.d. | I22: 338.409 | J22: 24 | K22: =R_256*I22/J22 -> 15341.208 | L22: =K22/F22*1000 -> 16407.709 | M22: S90
A23: S51 | B23: SHA3-256 | C23: [16] | D23: Virtex-5 | E23: 1 r/c, solo core — senza wrapper | F23: 1117 | G23: slice | H23: n.d. | I23: 189 | J23: 25 | K23: =R_256*I23/J23 -> 8225.28 | L23: =K23/F23*1000 -> 7363.7243 | M23: S90, S91
A24: S41 | B24: SHA3-256 | C24: [15] | D24: Virtex-5 | E24: pipeline | F24: 1163 | G24: slice | H24: n.d. | I24: 273 | J24: 48 | K24: =R_256*I24/J24 -> 6188 | L24: =K24/F24*1000 -> 5320.7223 | M24: S90, S91
A25: S40 | B25: SHA3-256 | C25: [15] | D25: Virtex-5 | E25: base | F25: 1192 | G25: slice | H25: n.d. | I25: 223 | J25: 24 | K25: =R_256*I25/J25 -> 10109.333 | L25: =K25/F25*1000 -> 8480.9843 | M25: S90, S91, SA0
A26: S21 | B26: SHA3-256 | C26: [12] | D26: Virtex-5 | E26: 1 r/c — originale | F26: 1434 | G26: slice | H26: 2640 | I26: 111.732 | J26: 24 | K26: =R_256*I26/J26 -> 5065.184 | L26: =K26/F26*1000 -> 3532.2064 | M26: S90, S91, SA0
A27: S32 | B27: SHA3-256 | C27: [13] | D27: Virtex-5 | E27: 1 r/c — senza pipeline | F27: 1581 | G27: slice | H27: n.d. | I27: 382 | J27: 24 | K27: =R_256*I27/J27 -> 17317.333 | L27: =K27/F27*1000 -> 10953.405 | M27: S91, SA0
A28: S12 | B28: SHA3-256 | C28: [11] | D28: Virtex-5 | E28: 1 r/c + interfaccia 64 bit (Keccak 2014) | F28: 1647 | G28: slice | H28: n.d. | I28: 137.01 | J28: 41 | K28: =R_256*I28/J28 -> 3635.7776 | L28: =K28/F28*1000 -> 2207.5152 | M28: S90, S91, SA0
A29: S60 | B29: SHA3-256 | C29: [17] | D29: Virtex-5 | E29: pipeline a 2 stadi nel round | F29: 1702 | G29: slice | H29: n.d. | I29: 389 | J29: 48 | K29: =R_256*I29/J29 -> 8817.3333 | L29: =K29/F29*1000 -> 5180.5719 | M29: S90, S91, SA0
A30: S50 | B30: SHA3-256 | C30: [16] | D30: Virtex-5 | E30: 1 r/c + wrapper/padding — con wrapper | F30: 1971 | G30: slice | H30: n.d. | I30: 195.733 | J30: 25 | K30: =R_256*I30/J30 -> 8518.3002 | L30: =K30/F30*1000 -> 4321.8164 | M30: S90, S91, SA0
A31: S20 | B31: SHA3-256 | C31: [12] | D31: Virtex-5 | E31: 3 round in 2 cicli — srotolato | F31: 2636 | G31: slice | H31: 2652 | I31: 84.21 | J31: 16 | K31: =R_256*I31/J31 -> 5726.28 | L31: =K31/F31*1000 -> 2172.3369 | M31: S90, S91, SA0
A32: S33 | B32: SHA3-256 | C32: [13] | D32: Virtex-5 | E32: 1 r/c, pipeline esterna a 2 stadi | F32: 2652 | G32: slice | H32: n.d. | I32: 352 | J32: 24 | K32: =R_256*I32/J32 -> 15957.333 | L32: =K32/F32*1000 -> 6017.094 | M32: S91, SA0
A33: S73 | B33: SHA3-256 | C33: [18] | D33: Spartan-6 | E33: compatto (lightweight), BRAM | F33: 127 | G33: slice | H33: n.d. | I33: =1000/5.07 -> 197.23866 | K33: 57 | L33: =K33/F33*1000 -> 448.8189 | M33: S72
A34: S77 | B34: SHA3-256 | C34: [18] | D34: Virtex-6 | E34: compatto (lightweight), BRAM | F34: 129 | G34: slice | H34: n.d. | I34: =1000/3.84 -> 260.41667 | K34: 75.2 | L34: =K34/F34*1000 -> 582.94574 | M34: S76
A35: S81 | B35: SHA3-256 | C35: [19] | D35: Virtex-6 | E35: 1 r/c (versione base) — 1 stadio | F35: 1019 | G35: slice | H35: n.d. | I35: 376.081 | J35: 24 | K35: =R_256*I35/J35 -> 17049.005 | L35: =K35/F35*1000 -> 16731.114 | M35: S92
A36: SD1 | B36: SHA3-256 | C36: [29] | D36: Virtex-6 | E36: 1 r/c (LUT6 con INIT condiviso) | F36: 1048 | G36: slice | H36: n.d. | I36: 194.78 | J36: 24 | K36: =R_256*I36/J36 -> 8830.0267 | L36: =K36/F36*1000 -> 8425.598 | M36: S92
A37: S34 | B37: SHA3-256 | C37: [13] | D37: Virtex-6 | E37: 1 r/c — senza pipeline | F37: 1115 | G37: slice | H37: n.d. | I37: 412 | J37: 24 | K37: =R_256*I37/J37 -> 18677.333 | L37: =K37/F37*1000 -> 16750.972 | M37: S92
A38: S13 | B38: SHA3-256 | C38: [11] | D38: Virtex-6 | E38: 1 r/c + interfaccia 64 bit (Keccak 2014) | F38: 1181 | G38: slice | H38: n.d. | I38: 251.7 | J38: 41 | K38: =R_256*I38/J38 -> 6679.2585 | L38: =K38/F38*1000 -> 5655.5957 | M38: S92
A39: SB3 | B39: SHA3-256 | C39: [28] | D39: Virtex-6 | E39: SHA-3 standalone — Ref_SHA-3 standalone | F39: 1345 | G39: slice | H39: n.d. | I39: n.d. | K39: 13960 | L39: =K39/F39*1000 -> 10379.182 | M39: S92, S93
A40: SA1 | B40: SHA3-256 | C40: [21] | D40: Virtex-6 | E40: unrolling + pipelining | F40: 1348 | G40: slice | H40: n.d. | I40: 344.62 | K40: 31246 | L40: =K40/F40*1000 -> 23179.525 | M40: S93
...

Sheet In attesa
A1: ⏳ Fonti primarie da ricevere: cosa manca e cosa sbloccano.
A2: Rif. | B2: Fonte | C2: Dati mancanti | D2: Perché serve
A3: GAJ12 | B3: Gaj et al., ePrint 2012/368 | C3: Keccak-256/512 su Altera (ALUT; Stratix III/IV, Cyclone) e Xilinx (slice) | D3: Benchmark canonico SHA-3. Stesso problema: PDF non leggibile per intero dal web.
A4: WONG | B4: Wong et al., ISCAS 2018 | C4: Le altre 4 varianti (871/153 MHz/24 c; 1393/335; 2145/45; 1416/85 secondo Sideris 2024) | D4: La variante a 871 slice potrebbe stare sul fronte Virtex-6 a bassa area.
A5: ELMOUMNI | B5: El Moumni et al., Microelectronics J. 2019 | C5: Varianti Virtex-5 e a 12 cicli (1365/2144 slice su V5, 3557 su V6 secondo Sideris 2024) | D5: Possibili punti sul fronte Virtex-5.
A6: HOMS15 | B6: Homsirikamol & Gaj, ARC 2015 | C6: Area, Fmax e cicli delle versioni HLS e RTL di Keccak | D6: Riga HLS su Virtex-6.
A7: JACINTO | B7: Jacinto et al., MWSCAS 2017 | C7: Area (LUT/slice) e Fmax su Zynq-7000 (2000 Mbps, 70 cicli) | D7: Riga HLS su Zynq-7000.
A8: — | B8: Core compatti citati da Sundal & Chaves (Tab. I): Jungk, San & At, Winderickx, Pereira, Akin | C8: Valori primari (oggi solo da fonte secondaria) | D8: Non fanno parte del perimetro di ricerca; potrebbero spostare il fronte Virtex-5 a bassa area.

Sheet Fonti
A1: N. | B1: Rif. | C1: Riferimento | D1: Accesso | E1: Link
A2: [1] | B2: GMU-R2 | C2: K. Mohajerani et al., "FPGA Benchmarking of Round 2 Candidates in the NIST Lightweight Cryptography Standardization Process", Cryptology ePrint 2020/1207 | D2: PDF fornito (244 pagine): tabelle Artix-7 e Appendice A (Tab. 22–24, 28, 32, 36) lette il 30/10 | E2: https://eprint.iacr.org/2020/1207
A3: [2] | B3: GMU-FIN | C3: K. Mohajerani et al., "SCA Evaluation and Benchmarking of Finalists in the NIST LWC Standardization Process", Cryptology ePrint 2023/484 | D3: PDF letto il 23/10 | E3: https://eprint.iacr.org/2023/484
A4: [3] | B4: KHAN23 | C4: S. Khan et al., "Area–Time Efficient Implementation of NIST Lightweight Hash Functions Targeting IoT Applications", IEEE IoT-J 10(9), 2023 | D4: PDF letto il 23/10
A5: [4] | B5: RECO-ASCON | C5: M. El-Hadedy et al., "RECO-ASCON: Reconfigurable ASCON hash functions for IoT applications", Integration 93, 2023 | D5: PDF nel repo (paper/ascon)
A6: [5] | B6: RECO-HCON | C6: X. Wei et al., "RECO-HCON: A High-Throughput Reconfigurable Compact ASCON Processor for Trusted IoT", IEEE SOCC 2022 | D6: PDF letto il 23/10
A7: [6] | B7: REZV | C7: B. Rezvani, F. Coleman, S. Sachin, W. Diehl, "Hardware Implementations of NIST Lightweight Cryptographic Candidates: A First Look", Cryptology ePrint 2019/824 (rev. 2020) | D7: PDF fornito (versione Round 2) | E7: https://eprint.iacr.org/2019/824
A8: [7] | B8: KERCK | C8: S. Kerckhof et al., "Compact FPGA Implementations of the Five SHA-3 Finalists", CARDIS 2011 | D8: PDF letto il 23/10
A9: [8] | B9: CHOUD | C9: R. Choudhary et al., "ASCON-KECCAK AEAD: A Novel Hardware Architecture for Cryptographic Processing", TechRxiv 2026 (preprint) | D9: PDF letto il 23/10
A10: [9] | B10: URBANO | C10: F. A. Urbano-Molano, J. Velasco-Medina, "SHA-3 Implementation for Post-Quantum Cryptography using High-Level Synthesis", SPL 2023 | D10: PDF letto il 23/10
A11: [10] | B11: AMD-VSL | C11: AMD, Vitis Security Library — SHA-3 (docs v2020.1 / v2026.1) | D11: documentazione web
A12: [11] | B12: HONDA | C12: T. Honda, H. Guntur, A. Satoh, "FPGA Implementation of New Standard Hash Function Keccak", IEEE GCCE 2014, pp. 275–279 | D12: PDF fornito | E12: https://ieeexplore.ieee.org/document/7031105
A13: [12] | B13: GHOL | C13: A. Gholipour, S. Mirzakuchaki, "Throughput Optimum Architecture of KECCAK Hash Function", IJCEE 4(6), 2012 | D13: PDF fornito
A14: [13] | B14: IOANNOU | C14: L. Ioannou, H. E. Michail, A. G. Voyiatzis, "High Performance Pipelined FPGA Implementation of the SHA-3 Hash Algorithm", MECO 2015, pp. 68–71 | D14: PDF fornito / nel repo
A15: [14] | B15: KERM | C15: A. Kermiche, M. Saoudi, A. Drouiche, "High throughput pipelined implementation of SHA3 hash algorithm on FPGA", J. Cryptogr. Eng. 15:15, 2025 | D15: PDF fornito | E15: https://doi.org/10.1007/s13389-025-00379-3
A16: [15] | B16: SUNDAL | C16: M. Sundal, R. Chaves, "Efficient FPGA Implementation of the SHA-3 Hash Function", IEEE ISVLSI 2017 | D16: PDF nel repo (paper/sha3)
A17: [16] | B17: BALDWIN | C17: B. Baldwin et al., "FPGA Implementations of the Round Two SHA-3 Candidates", FPL 2010 | D17: PDF nel repo (paper/sha3)
A18: [17] | B18: ATHAN | C18: G. S. Athanasiou, G.-P. Makkas, G. Theodoridis, "High Throughput Pipelined FPGA Implementation of the New SHA-3 Cryptographic Hash Algorithm", ISCCSP 2014, pp. 538–541 | D18: PDF nel repo (paper/sha3)
A19: [18] | B19: KAPS | C19: J.-P. Kaps et al., "Lightweight Implementations of SHA-3 Finalists on FPGAs" (GMU; sede e anno non riportati nel PDF) | D19: PDF open access (web) | E19: https://cryptography.gmu.edu/team/download.php?docid=2003
A20: [19] | B20: ASSAD | C20: F. Assad, M. Fettach, F. El Otmani, A. Tragha, "High-performance FPGA implementation of the secure hash algorithm 3 for single and multi-message processing", IJECE 12(2):1324–1333, 2022 | D20: PDF open access (web) | E20: https://ijece.iaescore.com/index.php/IJECE/article/view/25892
A21: [20] | B21: SID24 | C21: A. Sideris, T. Sanida, M. Dasygenis, "Hardware acceleration design of the SHA-3 for high throughput and low area on FPGA", J. Cryptogr. Eng. 14:193–205, 2024 | D21: PDF nel repo (paper/sha3) | E21: https://doi.org/10.1007/s13389-023-00334-0
A22: [21] | B22: SID23 | C22: A. Sideris, T. Sanida, M. Dasygenis, "A Novel Hardware Architecture for Enhancing the Keccak Hash Function in FPGA Devices", Information 14(9):475, 2023 | D22: HTML open access (web) | E22: https://www.mdpi.com/2078-2489/14/9/475
A23: [22] | B23: SID20 | C23: A. Sideris, T. Sanida, M. Dasygenis, "High Throughput Pipelined Implementation of the SHA-3 Cryptoprocessor", ICM 2020 | D23: PDF fornito
A24: [23] | B24: SID22 | C24: A. Sideris et al., "Acceleration of Image Processing with SHA-3 (Keccak) Algorithm using FPGA", JENRS 1(7):20–28, 2022 | D24: PDF fornito
A25: [24] | B25: SIDTECH | C25: A. Sideris, T. Sanida, M. Dasygenis, "High Throughput Implementation of the Keccak Hash Function Using the Nios-II Processor", Technologies 8(1):15, 2020 | D25: HTML open access (web) | E25: https://www.mdpi.com/2227-7080/8/1/15
A26: [25] | B26: SRAV | C26: M. M. Sravani, S. A. Durai, "On Efficiency Enhancement of SHA-3 for FPGA-Based Multimodal Biometric Authentication", IEEE TVLSI, 2022 | D26: PDF letto il 23/10
A27: [26] | B27: WONG | C27: M. M. Wong, J. Haj-Yahya, S. Sau, A. Chattopadhyay, "A New High Throughput and Area Efficient SHA-3 Implementation", ISCAS 2018 | D27: PDF letto il 23/10 (parziale)
A28: [27] | B28: ELMOUMNI | C28: S. El Moumni, M. Fettach, A. Tragha, "High throughput implementation of SHA3 hash algorithm on FPGA", Microelectronics J. 93:104615, 2019 | D28: PDF letto il 23/10 (parziale)
A29: [28] | B29: KUNDI | C29: D. Kundi et al., "Resource-Shared Crypto-Coprocessor of AES Enc/Dec With SHA-3", IEEE TCAS-I 67(12), 2020 | D29: PDF letto il 23/10
A30: [29] | B30: RAO19 | C30: M. Rao, T. Newe, I. Grout, "Secure Hash Algorithm-3 (SHA-3) implementation on Xilinx FPGAs, Suitable for IoT Applications", IJSSIS, 2019 | D30: PDF open access (web) | E30: https://core.ac.uk/download/304199727.pdf
A31: [30] | B31: MAACHE | C31: A. Maache, A. Kalache, "Design and Implementation of a flexible Multi-purpose Cryptographic System on low cost FPGA", IJECES 14(1):45–58, 2023 | D31: PDF open access (web) | E31: https://hrcak.srce.hr/292680
A32: [31] | B32: BENS | C32: H. Bensalem, Y. Blaquière, Y. Savaria, "An Efficient OpenCL-Based Implementation of a SHA-3 Co-Processor on an FPGA-Centric Platform", IEEE TCAS-II 70(3):1144–1148, 2023 | D32: PDF fornito | E32: https://doi.org/10.1109/TCSII.2022.3223179
A33: [32] | B33: PRIMAS | C33: R. Primas, ascon-verilog (SP 800-232) | D33: risintesi su xck26 (sota-refs) | E33: https://github.com/rprimas/ascon-verilog
A34: [33] | B34: BLUELIGHT | C34: K. Mohajerani, BlueLight (Bluespec LWC implementations) | D34: risintesi su xck26 (sota-refs) | E34: https://github.com/kammoh/bluelight
A35: [34] | B35: KECCAK-TEAM | C35: Keccak team, Keccak hardware implementations v3.1 (high-speed core) | D35: risintesi su xck26 (sota-refs) | E35: https://keccak.team/hardware.html
A36: [35] | B36: QUESTO LAVORO | C36: ascon-sha3-hybrid-hls (LOG-004, report hls_impl_pnr / hls_run_impl.log) | D36: repository | E36: https://github.com/al3monni/ascon-sha3-hybrid-hls
A37: [36] | B37: CAST-SHA3 | C37: CAST Inc., SHA-3 Secure Hash Crypto Engine — product brief AMD / Intel | D37: datasheet (web) | E37: https://www.cast-inc.com/pdfs/cast_sha-3-brief-amd.pdf
A38: [37] | B38: CAST-ASCON | C38: CAST Inc., ASCON-F — implementation results | D38: pagina prodotto (web) | E38: https://www.cast-inc.com/security/encryption-primitives/ascon-f
A39: [38] | B39: XIP3030C | C39: Xiphera, XIP3030C Compact SHA-3 (pagine Lattice e Microchip) | D39: pagina prodotto (web) | E39: https://www.latticesemi.com/products/designsoftwareandip/intellectualproperty/ipcore/xipheracores/xip3030c
A40: [39] | B40: XIP2201B | C40: Xiphera, XIP2201B Balanced Ascon (pagina Lattice) | D40: pagina prodotto (web) | E40: https://www.latticesemi.com/products/designsoftwareandip/intellectualproperty/ipcore/xipheracores/xip2201b
...
